<?xml version="1.0" ?>
<!-- =================================================================================== -->
<!-- |    This document was autogenerated by xacro from k1-de.urdf.xacro               | -->
<!-- |    EDITING THIS FILE BY HAND IS NOT RECOMMENDED                                 | -->
<!-- =================================================================================== -->
<robot name="jaka_k1">
  <link name="world"/>
  <link name="base_link">
    <visual>
      <origin rpy="0 0 0" xyz="0 0 0.1"/>
      <geometry>
        <box size="0.1 0.1 0.2"/>
      </geometry>
      <material name="">
        <color rgba="0.898039215686275 0.917647058823529 0.929411764705882 1"/>
      </material>
    </visual>
  </link>
  <joint 
    name="fixed" 
    type="fixed">
    <parent 
      link="world"/>
    <child 
      link="base_link"/>
  </joint>
  <link name="rb1_base_link">
    <inertial>
      <origin rpy="0 0 0" xyz="-3.31565095654657E-05 6.06658445700958E-10 0.0527775535616378"/>
      <mass value="2.64748232797832"/>
      <inertia ixx="0.00473767215322111" ixy="-6.01260140902674E-12" ixz="-4.01841188870717E-06" iyy="0.00458794707334943" iyz="-2.9687959769089E-11" izz="0.00369251689531693"/>
    </inertial>
    <visual>
      <origin rpy="0 0 0" xyz="0 0 0"/>
      <geometry>
        <mesh filename="package://jaka_k1_description/k1-arm/meshes/base_link.STL"/>
      </geometry>
      <material name="">
        <color rgba="0.898039215686275 0.917647058823529 0.929411764705882 1"/>
      </material>
    </visual>
    <collision>
      <origin rpy="0 0 0" xyz="0 0 0"/>
      <geometry>
        <mesh filename="package://jaka_k1_description/k1-arm/meshes/base_link.STL"/>
      </geometry>
    </collision>
  </link>
  <link name="rb1_link1">
    <inertial>
      <origin rpy="0 0 0" xyz="-2.35625239158876E-06 -1.35718499887083E-06 0.163004779462566"/>
      <mass value="1.39323858725078"/>
      <inertia ixx="0.00277101603679727" ixy="2.24081564360281E-07" ixz="4.69181593963154E-08" iyy="0.00349546627377581" iyz="-8.48514478793776E-08" izz="0.00199034701623032"/>
    </inertial>
    <visual>
      <origin rpy="0 0 0" xyz="0 0 0"/>
      <geometry>
        <mesh filename="package://jaka_k1_description/k1-arm/meshes/l1.STL"/>
      </geometry>
      <material name="">
        <color rgba="0.898039215686275 0.917647058823529 0.929411764705882 1"/>
      </material>
    </visual>
    <collision>
      <origin rpy="0 0 0" xyz="0 0 0"/>
      <geometry>
        <mesh filename="package://jaka_k1_description/k1-arm/meshes/l1.STL"/>
      </geometry>
    </collision>
  </link>
  <link name="rb1_link2">
    <inertial>
      <origin rpy="0 0 0" xyz="1.70719795747343E-05 -0.0452985895049797 -0.000762969523669277"/>
      <mass value="2.70256589027321"/>
      <inertia ixx="0.00984923023290559" ixy="3.34236778110788E-06" ixz="-3.45240338191605E-10" iyy="0.0058863249170294" iyz="9.35432024805029E-05" izz="0.00747853673712881"/>
    </inertial>
    <visual>
      <origin rpy="0 0 0" xyz="0 0 0"/>
      <geometry>
        <mesh filename="package://jaka_k1_description/k1-arm/meshes/l2.STL"/>
      </geometry>
      <material name="">
        <color rgba="0.898039215686275 0.917647058823529 0.929411764705882 1"/>
      </material>
    </visual>
    <collision>
      <origin rpy="0 0 0" xyz="0 0 0"/>
      <geometry>
        <mesh filename="package://jaka_k1_description/k1-arm/meshes/l2.STL"/>
      </geometry>
    </collision>
  </link>
  <link name="rb1_link3">
    <inertial>
      <origin rpy="0 0 0" xyz="-0.00653004950921493 -0.00044341434769557 0.240316413279225"/>
      <mass value="3.7871760373498"/>
      <inertia ixx="0.0211524169329576" ixy="1.15284058924315E-06" ixz="0.000297895882841359" iyy="0.0213336690886476" iyz="-1.74651664628716E-05" izz="0.00408459583034351"/>
    </inertial>
    <visual>
      <origin rpy="0 0 0" xyz="0 0 0"/>
      <geometry>
        <mesh filename="package://jaka_k1_description/k1-arm/meshes/l3.STL"/>
      </geometry>
      <material name="">
        <color rgba="0.898039215686275 0.917647058823529 0.929411764705882 1"/>
      </material>
    </visual>
    <collision>
      <origin rpy="0 0 0" xyz="0 0 0"/>
      <geometry>
        <mesh filename="package://jaka_k1_description/k1-arm/meshes/l3.STL"/>
      </geometry>
    </collision>
  </link>
  <link name="rb1_link4">
    <inertial>
      <origin rpy="0 0 0" xyz="0.00464516996665754 -0.0316039129807936 0.000428109339727117"/>
      <mass value="1.47374330951411"/>
      <inertia ixx="0.00379329755249468" ixy="0.00016024514491874" ixz="2.06418198559234E-07" iyy="0.00225584916470549" iyz="8.03288748324757E-06" izz="0.00281134741970306"/>
    </inertial>
    <visual>
      <origin rpy="0 0 0" xyz="0 0 0"/>
      <geometry>
        <mesh filename="package://jaka_k1_description/k1-arm/meshes/l4.STL"/>
      </geometry>
      <material name="">
        <color rgba="0.898039215686275 0.917647058823529 0.929411764705882 1"/>
      </material>
    </visual>
    <collision>
      <origin rpy="0 0 0" xyz="0 0 0"/>
      <geometry>
        <mesh filename="package://jaka_k1_description/k1-arm/meshes/l4.STL"/>
      </geometry>
    </collision>
  </link>
  <link name="rb1_link5">
    <inertial>
      <origin rpy="0 0 0" xyz="-2.44328465898169E-06 0.00431111481326711 0.179548593293089"/>
      <mass value="2.15871033480836"/>
      <inertia ixx="0.0047855558049604" ixy="1.56230988682375E-07" ixz="1.49162493484437E-07" iyy="0.00487381295466304" iyz="-0.000346879851779597" izz="0.00185119354981229"/>
    </inertial>
    <visual>
      <origin rpy="0 0 0" xyz="0 0 0"/>
      <geometry>
        <mesh filename="package://jaka_k1_description/k1-arm/meshes/l5.STL"/>
      </geometry>
      <material name="">
        <color rgba="0.898039215686275 0.917647058823529 0.929411764705882 1"/>
      </material>
    </visual>
    <collision>
      <origin rpy="0 0 0" xyz="0 0 0"/>
      <geometry>
        <mesh filename="package://jaka_k1_description/k1-arm/meshes/l5.STL"/>
      </geometry>
    </collision>
  </link>
  <link name="rb1_link6">
    <inertial>
      <origin rpy="0 0 0" xyz="-2.27348084080869E-07 -0.0786926809394562 0.00633326144632802"/>
      <mass value="1.54448711895944"/>
      <inertia ixx="0.00348283709613141" ixy="2.23461243426087E-08" ixz="6.57886223819392E-09" iyy="0.00139138348799316" iyz="-0.000688825990394737" izz="0.00330168144543662"/>
    </inertial>
    <visual>
      <origin rpy="0 0 0" xyz="0 0 0"/>
      <geometry>
        <mesh filename="package://jaka_k1_description/k1-arm/meshes/l6.STL"/>
      </geometry>
      <material name="">
        <color rgba="0.898039215686275 0.917647058823529 0.929411764705882 1"/>
      </material>
    </visual>
    <collision>
      <origin rpy="0 0 0" xyz="0 0 0"/>
      <geometry>
        <mesh filename="package://jaka_k1_description/k1-arm/meshes/l6.STL"/>
      </geometry>
    </collision>
  </link>
  <link name="rb1_link7">
    <inertial>
      <origin rpy="0 0 0" xyz="2.69416194742522E-07 -2.91492480236771E-05 0.161465913164776"/>
      <mass value="0.641939994235648"/>
      <inertia ixx="0.000376255873847744" ixy="3.53053559042807E-13" ixz="3.03203067830102E-13" iyy="0.000376762309704439" iyz="4.34928234651434E-07" izz="0.000517849992494949"/>
    </inertial>
    <visual>
      <origin rpy="0 0 0" xyz="0 0 0"/>
      <geometry>
        <mesh filename="package://jaka_k1_description/k1-arm/meshes/l7.STL"/>
      </geometry>
      <material name="">
        <color rgba="1 1 1 1"/>
      </material>
    </visual>
    <collision>
      <origin rpy="0 0 0" xyz="0 0 0"/>
      <geometry>
        <mesh filename="package://jaka_k1_description/k1-arm/meshes/l7.STL"/>
      </geometry>
    </collision>
  </link>
  <link name="rb1_tool">
    <inertial>
      <origin rpy="0 0 0" xyz="-5.55111512312578E-17 -2.77555756156289E-17 -0.00099999999999989"/>
      <mass value="0.00155862265526229"/>
      <inertia ixx="9.71784989903379E-08" ixy="-1.43769664088572E-23" ixz="-3.30488135350621E-23" iyy="9.71784989903378E-08" iyz="-4.9579971002013E-24" izz="1.93317916210501E-07"/>
    </inertial>
    <visual>
      <origin rpy="0 0 0" xyz="0 0 0"/>
      <geometry>
        <mesh filename="package://jaka_k1_description/k1-arm/meshes/lt.STL"/>
      </geometry>
      <material name="">
        <color rgba="0.792156862745098 0.819607843137255 0.933333333333333 1"/>
      </material>
    </visual>
    <collision>
      <origin rpy="0 0 0" xyz="0 0 0"/>
      <geometry>
        <mesh filename="package://jaka_k1_description/k1-arm/meshes/lt.STL"/>
      </geometry>
    </collision>
  </link>
  <!-- DH_PARAM = {203, 0, 340.5, 0, 227, 0, 188, 0, 0, 0, 0, 0, 0, 0, 0.0, 0.0, 0.0, 0.0,
        0.0, 0.0, 0.0, -90, 90, -90, 90, -90, 90, 0.0} -->
  <!-- JOINT_OFFSET = {180, 0, 0, 0, 180, 0, 0} -->
  <!-- JOINT_DIR = {1, -1, 1, 1, 1, 1, 1} -->
  <joint name="rb1_install" type="fixed">
    <origin rpy="1.5708 -1.5708 3.14159" xyz="0 0.016 0.22"/>
    <parent link="base_link"/>
    <child link="rb1_base_link"/>
  </joint>
  <joint name="rb1_j1" type="revolute">
    <origin rpy="0 0 -1.5708" xyz="0 0 0"/>
    <parent link="rb1_base_link"/>
    <child link="rb1_link1"/>
    <axis xyz="0 0 1"/>
    <limit effort="0" lower="-6.2832" upper="6.2832" velocity="0"/>
  </joint>
  <joint name="rb1_j2" type="revolute">
    <origin rpy="-1.5708 0 0" xyz="0 0 0.203"/>
    <parent link="rb1_link1"/>
    <child link="rb1_link2"/>
    <axis xyz="0 0 1"/>
    <limit effort="0" lower="-1.8325" upper="1.8325" velocity="0"/>
  </joint>
  <joint name="rb1_j3" type="revolute">
    <origin rpy="-1.5708 0 3.1416" xyz="0 0 0"/>
    <parent link="rb1_link2"/>
    <child link="rb1_link3"/>
    <axis xyz="0 0 1"/>
    <limit effort="0" lower="-6.2832" upper="6.2832" velocity="0"/>
  </joint>
  <joint name="rb1_j4" type="revolute">
    <origin rpy="-1.5708 0 -3.1416" xyz="0.00040047 0 0.3405"/>
    <parent link="rb1_link3"/>
    <child link="rb1_link4"/>
    <axis xyz="0 0 1"/>
    <limit effort="0" lower="-2.5307" upper="0.5235" velocity="0"/>
  </joint>
  <joint name="rb1_j5" type="revolute">
    <origin rpy="-1.5708 0 -3.1416" xyz="0 0 0"/>
    <parent link="rb1_link4"/>
    <child link="rb1_link5"/>
    <axis xyz="0 0 1"/>
    <limit effort="0" lower="-6.2832" upper="6.2832" velocity="0"/>
  </joint>
  <joint name="rb1_j6" type="revolute">
    <origin rpy="-1.5708 0 -3.1416" xyz="0 0 0.22694"/>
    <parent link="rb1_link5"/>
    <child link="rb1_link6"/>
    <axis xyz="0 0 1"/>
    <limit effort="0" lower="-1.8325" upper="1.8325" velocity="0"/>
  </joint>
  <joint name="rb1_j7" type="revolute">
    <origin rpy="1.5708 0 0" xyz="0 0 0"/>
    <parent link="rb1_link6"/>
    <child link="rb1_link7"/>
    <axis xyz="0 0 1"/>
    <limit effort="0" lower="-6.2832" upper="6.2832" velocity="0"/>
  </joint>
  <joint name="rb1_t" type="fixed">
    <origin rpy="0 0 0" xyz="0 0 0.18827"/>
    <parent link="rb1_link7"/>
    <child link="rb1_tool"/>
    <axis xyz="0 0 1"/>
    <limit effort="0" lower="0" upper="0" velocity="0"/>
  </joint>
  <!-- <xacro:joint name="r-j5" parent="base_link"        child="r5"  xyz="3 0 0"         rpy="1.5708 0
        -3.1416"  lower="-6.2832" upper="6.2832"  /> -->
  <!-- <xacro:joint name="r-j6" parent="base_link"        child="r6"  xyz="3 0 $(arg d5)" rpy="-1.5708
        0 0"       lower="-1.8325" upper="1.8325"  /> -->
  <!-- <xacro:joint name="r-j7" parent="base_link"        child="r7"  xyz="3 0 0"         rpy="1.5708 0 0"
        lower="-6.2832" upper="6.2832"  /> -->
  <!-- <xacro:joint name="r-t"  parent="base_link"        child="rt"  xyz="3 0 0.188"     rpy="0 0 0"
        lower="-6.2832" upper="6.2832"  type="fixed" axis="0 0 0"/> -->
  <link name="rb2_base_link">
    <inertial>
      <origin rpy="0 0 0" xyz="3.31565095654518E-05 -6.06658362434231E-10 0.0527775535616377"/>
      <mass value="2.64748232797832"/>
      <inertia ixx="0.00473767215322111" ixy="-6.01260149388541E-12" ixz="4.01841188870722E-06" iyy="0.00458794707334943" iyz="2.9687960037144E-11" izz="0.00369251689531694"/>
    </inertial>
    <visual>
      <origin rpy="0 0 0" xyz="0 0 0"/>
      <geometry>
        <mesh filename="package://jaka_k1_description/k1-arm/meshes/base_link.STL"/>
      </geometry>
      <material name="">
        <color rgba="0.898039215686275 0.917647058823529 0.929411764705882 1"/>
      </material>
    </visual>
    <collision>
      <origin rpy="0 0 0" xyz="0 0 0"/>
      <geometry>
        <mesh filename="package://jaka_k1_description/k1-arm/meshes/base_link.STL"/>
      </geometry>
    </collision>
  </link>
  <link name="rb2_link1">
    <inertial>
      <origin rpy="0 0 0" xyz="2.35625309155663E-06 1.35718496940829E-06 0.163004779462571"/>
      <mass value="1.39323858725092"/>
      <inertia ixx="0.00277101603679751" ixy="2.24081564361421E-07" ixz="-4.69181628062515E-08" iyy="0.00349546627377609" iyz="8.48514480750015E-08" izz="0.00199034701623053"/>
    </inertial>
    <visual>
      <origin rpy="0 0 0" xyz="0 0 0"/>
      <geometry>
        <mesh filename="package://jaka_k1_description/k1-arm/meshes/r1.STL"/>
      </geometry>
      <material name="">
        <color rgba="0.898039215686275 0.917647058823529 0.929411764705882 1"/>
      </material>
    </visual>
    <collision>
      <origin rpy="0 0 0" xyz="0 0 0"/>
      <geometry>
        <mesh filename="package://jaka_k1_description/k1-arm/meshes/r1.STL"/>
      </geometry>
    </collision>
  </link>
  <link name="rb2_link2">
    <inertial>
      <origin rpy="0 0 0" xyz="-1.71093757588003E-05 -0.0452985721312214 0.000762955289202616"/>
      <mass value="2.70256307184887"/>
      <inertia ixx="0.00984922872707295" ixy="-3.34424080739915E-06" ixz="1.12868359949668E-09" iyy="0.00588632047318319" iyz="-9.3543917494047E-05" izz="0.00747853193882291"/>
    </inertial>
    <visual>
      <origin rpy="0 0 0" xyz="0 0 0"/>
      <geometry>
        <mesh filename="package://jaka_k1_description/k1-arm/meshes/r2.STL"/>
      </geometry>
      <material name="">
        <color rgba="0.898039215686275 0.917647058823529 0.929411764705882 1"/>
      </material>
    </visual>
    <collision>
      <origin rpy="0 0 0" xyz="0 0 0"/>
      <geometry>
        <mesh filename="package://jaka_k1_description/k1-arm/meshes/r2.STL"/>
      </geometry>
    </collision>
  </link>
  <link name="rb2_link3">
    <inertial>
      <origin rpy="0 0 0" xyz="0.00652991308253514 -0.000442905212810041 -0.240316417923352"/>
      <mass value="3.78717603752458"/>
      <inertia ixx="0.021152417271302" ixy="-1.15346166484228E-06" ixz="0.000297886191537816" iyy="0.0213336690144706" iyz="1.75017113835126E-05" izz="0.00408459556648683"/>
    </inertial>
    <visual>
      <origin rpy="0 0 0" xyz="0 0 0"/>
      <geometry>
        <mesh filename="package://jaka_k1_description/k1-arm/meshes/r3.STL"/>
      </geometry>
      <material name="">
        <color rgba="0.898039215686275 0.917647058823529 0.929411764705882 1"/>
      </material>
    </visual>
    <collision>
      <origin rpy="0 0 0" xyz="0 0 0"/>
      <geometry>
        <mesh filename="package://jaka_k1_description/k1-arm/meshes/r3.STL"/>
      </geometry>
    </collision>
  </link>
  <link name="rb2_link4">
    <inertial>
      <origin rpy="0 0 0" xyz="0.00464514960444359 0.0316039318322144 -0.000428082645444083"/>
      <mass value="1.47374297939438"/>
      <inertia ixx="0.00379329593223484" ixy="-0.000160244508046095" ixz="-2.05545994070888E-07" iyy="0.00225584817402452" iyz="8.0341089919647E-06" izz="0.00281134619295324"/>
    </inertial>
    <visual>
      <origin rpy="0 0 0" xyz="0 0 0"/>
      <geometry>
        <mesh filename="package://jaka_k1_description/k1-arm/meshes/r4.STL"/>
      </geometry>
      <material name="">
        <color rgba="0.898039215686275 0.917647058823529 0.929411764705882 1"/>
      </material>
    </visual>
    <collision>
      <origin rpy="0 0 0" xyz="0 0 0"/>
      <geometry>
        <mesh filename="package://jaka_k1_description/k1-arm/meshes/r4.STL"/>
      </geometry>
    </collision>
  </link>
  <link name="rb2_link5">
    <inertial>
      <origin rpy="0 0 0" xyz="2.4267981551529E-06 -0.00431111479965585 0.179548593384493"/>
      <mass value="2.15871033311329"/>
      <inertia ixx="0.00478555580296053" ixy="1.56222935791537E-07" ixz="-1.49192463873201E-07" iyy="0.00487381295205347" iyz="0.000346879850784245" izz="0.001851193548143"/>
    </inertial>
    <visual>
      <origin rpy="0 0 0" xyz="0 0 0"/>
      <geometry>
        <mesh filename="package://jaka_k1_description/k1-arm/meshes/r5.STL"/>
      </geometry>
      <material name="">
        <color rgba="0.898039215686275 0.917647058823529 0.929411764705882 1"/>
      </material>
    </visual>
    <collision>
      <origin rpy="0 0 0" xyz="0 0 0"/>
      <geometry>
        <mesh filename="package://jaka_k1_description/k1-arm/meshes/r5.STL"/>
      </geometry>
    </collision>
  </link>
  <link name="rb2_link6">
    <inertial>
      <origin rpy="0 0 0" xyz="-2.27348336573341E-07 -0.0786926809396099 0.0063285262352254"/>
      <mass value="1.5444871189577"/>
      <inertia ixx="0.00348283709608049" ixy="2.23461240922036E-08" ixz="6.57882835617852E-09" iyy="0.00139138348799037" iyz="-0.000688825990372178" izz="0.003301681445464"/>
    </inertial>
    <visual>
      <origin rpy="0 0 0" xyz="0 0 0"/>
      <geometry>
        <mesh filename="package://jaka_k1_description/k1-arm/meshes/r6.STL"/>
      </geometry>
      <material name="">
        <color rgba="0.898039215686275 0.917647058823529 0.929411764705882 1"/>
      </material>
    </visual>
    <collision>
      <origin rpy="0 0 0" xyz="0 0 0"/>
      <geometry>
        <mesh filename="package://jaka_k1_description/k1-arm/meshes/r6.STL"/>
      </geometry>
    </collision>
  </link>
  <link name="rb2_link7">
    <inertial>
      <origin rpy="0 0 0" xyz="1.53433398486502E-07 -3.38533751887971E-05 0.161465913171448"/>
      <mass value="0.641939994235649"/>
      <inertia ixx="0.000376255873847819" ixy="-3.12488196269271E-13" ixz="-1.01726480817797E-10" iyy="0.000376762309871897" iyz="4.34955394700917E-07" izz="0.00051784999232742"/>
    </inertial>
    <visual>
      <origin rpy="0 0 0" xyz="0 0 0"/>
      <geometry>
        <mesh filename="package://jaka_k1_description/k1-arm/meshes/r7.STL"/>
      </geometry>
      <material name="">
        <color rgba="1 1 1 1"/>
      </material>
    </visual>
    <collision>
      <origin rpy="0 0 0" xyz="0 0 0"/>
      <geometry>
        <mesh filename="package://jaka_k1_description/k1-arm/meshes/r7.STL"/>
      </geometry>
    </collision>
  </link>
  <link name="rb2_tool">
    <inertial>
      <origin rpy="0 0 0" xyz="7.18437198621302E-10 -1.92504762130952E-10 -0.00099999999999989"/>
      <mass value="0.00155862265526229"/>
      <inertia ixx="9.71784989903875E-08" ixy="-1.32853506615153E-20" ixz="-6.90701328598647E-14" iyy="9.71784989903415E-08" iyz="1.85072947766703E-14" izz="1.93317916210448E-07"/>
    </inertial>
    <visual>
      <origin rpy="0 0 0" xyz="0 0 0"/>
      <geometry>
        <mesh filename="package://jaka_k1_description/k1-arm/meshes/rt.STL"/>
      </geometry>
      <material name="">
        <color rgba="0.792156862745098 0.819607843137255 0.933333333333333 1"/>
      </material>
    </visual>
    <collision>
      <origin rpy="0 0 0" xyz="0 0 0"/>
      <geometry>
        <mesh filename="package://jaka_k1_description/k1-arm/meshes/rt.STL"/>
      </geometry>
    </collision>
  </link>
  <!-- DH_PARAM = {203, 0, 340.5, 0, 227, 0, 188, 0, 0, 0, 0, 0, 0, 0, 0.0, 0.0, 0.0, 0.0,
        0.0, 0.0, 0.0, -90, 90, -90, 90, -90, 90, 0.0} -->
  <!-- JOINT_OFFSET = {180, 0, 0, 0, 180, 0, 0} -->
  <!-- JOINT_DIR = {1, -1, 1, 1, 1, 1, 1} -->
  <joint name="rb2_install" type="fixed">
    <origin rpy="1.5708 1.5708 0" xyz="0 -0.016 0.22"/>
    <parent link="base_link"/>
    <child link="rb2_base_link"/>
  </joint>
  <joint name="rb2_j1" type="revolute">
    <origin rpy="0 0 -1.5708" xyz="0 0 0"/>
    <parent link="rb2_base_link"/>
    <child link="rb2_link1"/>
    <axis xyz="0 0 1"/>
    <limit effort="0" lower="-6.2832" upper="6.2832" velocity="0"/>
  </joint>
  <joint name="rb2_j2" type="revolute">
    <origin rpy="-1.5708 0 0" xyz="0 0 0.203"/>
    <parent link="rb2_link1"/>
    <child link="rb2_link2"/>
    <axis xyz="0 0 1"/>
    <limit effort="0" lower="-1.8325" upper="1.8325" velocity="0"/>
  </joint>
  <joint name="rb2_j3" type="revolute">
    <origin rpy="-1.5708 0 0" xyz="0 0 0"/>
    <parent link="rb2_link2"/>
    <child link="rb2_link3"/>
    <axis xyz="0 0 -1"/>
    <limit effort="0" lower="-6.2832" upper="6.2832" velocity="0"/>
  </joint>
  <joint name="rb2_j4" type="revolute">
    <origin rpy="-1.5708 0 0" xyz="-0.00040047 0 -0.3405"/>
    <parent link="rb2_link3"/>
    <child link="rb2_link4"/>
    <axis xyz="0 0 -1"/>
    <limit effort="0" lower="-2.5307" upper="0.5235" velocity="0"/>
  </joint>
  <joint name="rb2_j5" type="revolute">
    <origin rpy="1.5708 0 -3.1416" xyz="0 0 0"/>
    <parent link="rb2_link4"/>
    <child link="rb2_link5"/>
    <axis xyz="0 0 1"/>
    <limit effort="0" lower="-6.2832" upper="6.2832" velocity="0"/>
  </joint>
  <joint name="rb2_j6" type="revolute">
    <origin rpy="-1.5708 0 0" xyz="0 0 0.22694"/>
    <parent link="rb2_link5"/>
    <child link="rb2_link6"/>
    <axis xyz="0 0 1"/>
    <limit effort="0" lower="-1.8325" upper="1.8325" velocity="0"/>
  </joint>
  <joint name="rb2_j7" type="revolute">
    <origin rpy="1.5708 0 0" xyz="0 0 0"/>
    <parent link="rb2_link6"/>
    <child link="rb2_link7"/>
    <axis xyz="0 0 1"/>
    <limit effort="0" lower="-6.2832" upper="6.2832" velocity="0"/>
  </joint>
  <joint name="rb2_t" type="fixed">
    <origin rpy="0 0 0" xyz="0 0 0.18827"/>
    <parent link="rb2_link7"/>
    <child link="rb2_tool"/>
    <axis xyz="0 0 1"/>
    <limit effort="0" lower="0" upper="0" velocity="0"/>
  </joint>
  <!-- <xacro:joint name="r-j5" parent="base_link"        child="r5"  xyz="3 0 0"         rpy="1.5708 0
        -3.1416"  lower="-6.2832" upper="6.2832"  /> -->
  <!-- <xacro:joint name="r-j6" parent="base_link"        child="r6"  xyz="3 0 $(arg d5)" rpy="-1.5708
        0 0"       lower="-1.8325" upper="1.8325"  /> -->
  <!-- <xacro:joint name="r-j7" parent="base_link"        child="r7"  xyz="3 0 0"         rpy="1.5708 0 0"
        lower="-6.2832" upper="6.2832"  /> -->
  <!-- <xacro:joint name="r-t"  parent="base_link"        child="rt"  xyz="3 0 0.188"     rpy="0 0 0"
        lower="-6.2832" upper="6.2832"  type="fixed" axis="0 0 0"/> -->
</robot>
